2019-07-24 15:02:43,871 [ERROR]  Exception occurred while handling uri: 'http://localhost:5005/'
Traceback (most recent call last):
  File "c:\users\shadiwan\appdata\local\programs\python\python37\lib\site-packages\sanic\app.py", line 893, in handle_request
    handler, args, kwargs, uri = self.router.get(request)
  File "c:\users\shadiwan\appdata\local\programs\python\python37\lib\site-packages\sanic\router.py", line 407, in get
    return self._get(request.path, request.method, "")
  File "c:\users\shadiwan\appdata\local\programs\python\python37\lib\site-packages\sanic\router.py", line 469, in _get
    raise NotFound("Requested URL {} not found".format(url))
sanic.exceptions.NotFound: Requested URL / not found
2019-07-24 15:02:44,475 [ERROR]  Exception occurred while handling uri: 'http://localhost:5005/favicon.ico'
Traceback (most recent call last):
  File "c:\users\shadiwan\appdata\local\programs\python\python37\lib\site-packages\sanic\app.py", line 893, in handle_request
    handler, args, kwargs, uri = self.router.get(request)
  File "c:\users\shadiwan\appdata\local\programs\python\python37\lib\site-packages\sanic\router.py", line 407, in get
    return self._get(request.path, request.method, "")
  File "c:\users\shadiwan\appdata\local\programs\python\python37\lib\site-packages\sanic\router.py", line 469, in _get
    raise NotFound("Requested URL {} not found".format(url))
sanic.exceptions.NotFound: Requested URL /favicon.ico not found
